Workbook

Sheet ReadMe
A1: Dungeon Builder Option A archetype simulator
A3: How to use
A5: 1) Go to the Assumptions sheet to review global tuning knobs. Cells with yellow fill are intended to be edited.
A6: 2) Go to the Archetypes sheet and edit the yellow cells for each archetype. Three archetypes are prefilled: Safe, Balanced, Lethal.
A7: 3) Use Simulation_48h for hour by hour detail through 48 hours. Use Simulation_7d_6h for the full week at 6 hour steps. Both use Hours online per day from Assumptions.
A8: 4) Review the KPI sheet for 24 hour, 3 day, and 7 day snapshots plus warning flags.
A9: 5) If values behave strangely, adjust one knob at a time. The goal is to make optimization matter while keeping heat and upkeep as real pressure.

Sheet Assumptions
A1: Global assumptions and tuning knobs
A3: ECONOMY
A4: Core mana per level per minute | B4: 1.5 | C4: CoreLevel*2
A5: Floor mana per floor per minute | B5: 1 | C5: ActiveFloors*1
A6: Skill spill rate (online) | B6: 0.15 | C6: Damage*rate
A7: Skill spill retention (offline) | B7: 0.3 | C7: Start value, research can raise
A8: Negative heat mana efficiency | B8: 1.1 | C8: Applies when heat < 0
A9: Negative heat death mana factor | B9: 0.8 | C9: Multiplier on death mana when heat < 0
A10: Hours online per day | B10: 2 | C10: For the schedule in Simulation
A11: Spend percent of usable mana per hour (default) | B11: 0.2 | C11: Used if archetype does not override
A13: ELITES
A14: Base elite party chance | B14: 0.01 | C14: Baseline per party
A15: Elite chance rating slope | B15: 0.0002 | C15: Additional chance per rating point
A16: No low level monsters bonus | B16: 0.05 | C16: Added if NoLowLevelMonsters is Yes
A17: Elite chance cap | B17: 0.8 | C17: Maximum probability
A18: Elite multiplier (death and spill) | B18: 2.5 | C18: Locked value
A20: HEAT
A21: Heat min cap | B21: -15 | C21: Locked, configurable later
A22: Heat gain per normal adventurer death | B22: 1
A23: Heat gain per elite adventurer death | B23: 3
A24: Multi death bonus heat per party | B24: 0.1 | C24: Expected bonus heat per party
A25: Passive heat decay per hour (baseline) | B25: 0.15 | C25: Always applies
A26: Passive heat decay multiplier (research) | B26: 1 | C26: Set above 1 for research
A27: Survival cooling base per full survive run | B27: 0.4 | C27: Before depth and party size scaling
A28: Survival cooling depth slope | B28: 0.15 | C28: Per floor entered
A29: Survival cooling party size penalty slope | B29: 0.1 | C29: Larger party reduces cooling
A30: Loot cooling per 100 loot value extracted | B30: 0.1 | C30: Heat reduced per 100 value
A31: Heat traffic penalty slope | B31: 0.6 | C31: Traffic multiplier = 1 - slope*(heat/50), min 0.10
A32: Negative heat traffic bonus at min heat | B32: 0.4 | C32: Traffic boost when heat = min cap
A33: Negative heat level reduction at min heat | B33: 0.4 | C33: Percent reduction to adventurer level when heat = min cap
A34: Peace efficiency | B34: 1 | C34: Heat 0 to 9
A35: Notice efficiency | B35: 0.95 | C35: Heat 10 to 24
A36: Concern efficiency | B36: 0.85 | C36: Heat 25 to 49
A38: UPKEEP
A39: Upkeep base per monster | B39: 5 | C39: Reserved mana base
A40: Upkeep level slope | B40: 0.2 | C40: Linear part before threshold
A41: Upkeep threshold level | B41: 10 | C41: After this, exponential growth applies
A42: Upkeep exponential rate | B42: 0.1 | C42: Per level above threshold
A43: Tier 1 multiplier | B43: 1 | C43: Evolution tier 1
A44: Tier 2 multiplier | B44: 1.5 | C44: Evolution tier 2
...

Sheet Archetypes
A1: Archetypes side by side inputs and derived values
A3: Input or output | B3: Safe | C3: Balanced | D3: Lethal
A4: Stage (Early or Mid) | B4: Early | C4: Mid | D4: Mid
A5: Core level | B5: 1 | C5: 5 | D5: 8
A6: Active floors | B6: 1 | C6: 3 | D6: 5
A7: Starting total mana | B7: 0 | C7: 0 | D7: 0
A8: Starting heat | B8: 0 | C8: 5 | D8: 15
A9: Dungeon rating (from 25 floor model) | B9: 60 | C9: 140 | D9: 220
A10: No low level monsters (Yes or No) | B10: No | C10: No | D10: Yes
A11: Base parties per hour | B11: 10 | C11: 6 | D11: 3
A12: Average party size | B12: 2 | C12: 4 | D12: 5
A13: Average adventurer level | B13: 6 | C13: 12 | D13: 18
A14: Average depth reached (highest floor entered) | B14: 2 | C14: 3 | D14: 4
A15: Deaths per party (expected) | B15: 0.1 | C15: 0.5 | D15: 1.5
A16: Full party survival rate | B16: 0.75 | C16: 0.45 | D16: 0.2
A17: Tradeable loot extraction rate | B17: 0.9 | C17: 0.7 | D17: 0.4
A18: Loot tier index | B18: 1 | C18: 2 | D18: 3
A19: Loot rarity | B19: Uncommon | C19: Rare | D19: Elite
A20: Damage per party (normal) | B20: 1200 | C20: 3200 | D20: 6500
A21: Elite party damage multiplier | B21: 2.5 | C21: 2.5 | D21: 2.5
A22: Elite party deaths multiplier | B22: 1.2 | C22: 1.3 | D22: 1.4
A23: Monster count | B23: 12 | C23: 20 | D23: 28
A24: Average monster level | B24: 4 | C24: 10 | D24: 16
A25: Average evolution tier (1 to 3) | B25: 1.2 | C25: 1.6 | D25: 2.1
A26: Other reserved mana (loot, traps, etc.) | B26: 0 | C26: 25 | D26: 60
A27: Spend percent of usable mana per hour | B27: 0.2 | C27: 0.25 | D27: 0.3
A29: Derived outputs
A30: Elite party chance | B30: =MIN(Assumptions!$B$17,Assumptions!$B$14+Assumptions!$B$15*B9+IF(B10="Yes",Assumptions!$B$16,0)) -> 0.022 | C30: =MIN(Assumptions!$B$17,Assumptions!$B$14+Assumptions!$B$15*C9+IF(C10="Yes",Assumptions!$B$16,0)) -> 0.038 | D30: =MIN(Assumptions!$B$17,Assumptions!$B$14+Assumptions!$B$15*D9+IF(D10="Yes",Assumptions!$B$16,0)) -> 0.104
A31: Loot value per extracted run | B31: =Assumptions!$B$48*POWER(Assumptions!$B$49,B18-1)*INDEX(Assumptions!$B$53:$B$58,MATCH(B19,Assumptions!$A$53:$A$58,0)) -> 14 | C31: =Assumptions!$B$48*POWER(Assumptions!$B$49,C18-1)*INDEX(Assumptions!$B$53:$B$58,MATCH(C19,Assumptions!$A$53:$A$58,0)) -> 44 | D31: =Assumptions!$B$48*POWER(Assumptions!$B$49,D18-1)*INDEX(Assumptions!$B$53:$B$58,MATCH(D19,Assumptions!$A$53:$A$58,0)) -> 145.2
A32: Monster upkeep reserved mana | B32: =B23*((Assumptions!$B$39+Assumptions!$B$40*B24)*IF(B24>Assumptions!$B$41,POWER(1+Assumptions!$B$42,B24-Assumptions!$B$41),1))*IF(B25<=2,Assumptions!$B$43+(B25-1)*(Assumptions!$B$44-Assumptions!$B$43),Assumptions!$B$44+(B25-2)*(Assumptions!$B$45-Assumptions!$B$44)) -> 76.56 | C32: =C23*((Assumptions!$B$39+Assumptions!$B$40*C24)*IF(C24>Assumptions!$B$41,POWER(1+Assumptions!$B$42,C24-Assumptions!$B$41),1))*IF(C25<=2,Assumptions!$B$43+(C25-1)*(Assumptions!$B$44-Assumptions!$B$43),Assumptions!$B$44+(C25-2)*(Assumptions!$B$45-Assumptions!$B$44)) -> 182 | D32: =D23*((Assumptions!$B$39+Assumptions!$B$40*D24)*IF(D24>Assumptions!$B$41,POWER(1+Assumptions!$B$42,D24-Assumptions!$B$41),1))*IF(D25<=2,Assumptions!$B$43+(D25-1)*(Assumptions!$B$44-Assumptions!$B$43),Assumptions!$B$44+(D25-2)*(Assumptions!$B$45-Assumptions!$B$44)) -> 650.80065
A33: Total reserved mana | B33: =B36 -> 1996.56 | C33: =C36 -> 9054.36 | D33: =D36 -> 20717.201
A34: Loot items generated per party | B34: 1 | C34: 2 | D34: 3
A35: Infrastructure reserve | B35: =Assumptions!$B$65*B6*(1+Assumptions!$B$66*B9)*(1+Assumptions!$B$73*(B5-1)) -> 1920 | C35: =Assumptions!$B$65*C6*(1+Assumptions!$B$66*C9)*(1+Assumptions!$B$73*(C5-1)) -> 8847.36 | D35: =Assumptions!$B$65*D6*(1+Assumptions!$B$66*D9)*(1+Assumptions!$B$73*(D5-1)) -> 20006.4
A36: Fixed reserved mana (base) | B36: =B32+B26+B35+Assumptions!$B$46 -> 1996.56 | C36: =C32+C26+C35+Assumptions!$B$46 -> 9054.36 | D36: =D32+D26+D35+Assumptions!$B$46 -> 20717.201

Sheet Simulation_48h
A1: Simulation_48h simulation for three archetypes
F2: Safe | S2: Balanced | AF2: Lethal
A3: Step start hour | B3: Day | C3: Hour in day | D3: Online (1 or 0) | E3: Step hours | F3: Heat start | G3: Heat end | H3: Heat change | I3: Parties in step | J3: Elite chance | K3: Elite parties in step | L3: Deaths in step | M3: Full survive runs in step | N3: Mana gain in step | O3: Total mana end | P3: Reserved mana | Q3: Usable mana end | S3: Heat start | T3: Heat end | U3: Heat change | V3: Parties in step | W3: Elite chance | X3: Elite parties in step | Y3: Deaths in step | Z3: Full survive runs in step | AA3: Mana gain in step | AB3: Total mana end | AC3: Reserved mana | AD3: Usable mana end | AF3: Heat start | AG3: Heat end | AH3: Heat change | AI3: Parties in step | AJ3: Elite chance | AK3: Elite parties in step | AL3: Deaths in step | AM3: Full survive runs in step | AN3: Mana gain in step | AO3: Total mana end | AP3: Reserved mana | AQ3: Usable mana end
A4: 0 | B4: =INT(A4/24)+1 -> 1 | C4: =MOD(A4,24) -> 0 | D4: =IF(C4<Assumptions!$B$10,1,0) -> 1 | E4: 1 | F4: =Archetypes!$B$8 -> 0 | G4: =MAX(Assumptions!$B$21,F4+H4) -> -2.0701216 | H4: =((L4*(Assumptions!$B$22+((Assumptions!$B$23-Assumptions!$B$22)*IF(I4>0,K4/I4,0)))*(1+Assumptions!$B$60*(Archetypes!$B$13-1)))+IF(L4>I4,I4*Assumptions!$B$24,0)-IF(IF(I4>0,M4/I4,1)<Assumptions!$B$61,((M4*(Assumptions!$B$27*(1+Assumptions!$B$28*(Archetypes!$B$14-1))/(1+Assumptions!$B$29*(Archetypes!$B$12-1))))+(((I4*Archetypes!$B$17*IF(I4>0,M4/I4,1)*Archetypes!$B$31)/100)*Assumptions!$B$30))*Assumptions!$B$62,((M4*(Assumptions!$B$27*(1+Assumptions!$B$28*(Archetypes!$B$14-1))/(1+Assumptions!$B$29*(Archetypes!$B$12-1))))+(((I4*Archetypes!$B$17*IF(I4>0,M4/I4,1)*Archetypes!$B$31)/100)*Assumptions!$B$30)))-(Assumptions!$B$25*Assumptions!$B$26*E4))*E4 -> -2.0701216 | I4: =(Archetypes!$B$11*(IF(F4<0,1+Assumptions!$B$32*MIN(1,ABS(F4)/ABS(Assumptions!$B$21)),MAX(0.1,1-Assumptions!$B$31*(F4/50)))))*$E4 -> 10 | J4: =Archetypes!$B$30 -> 0.022 | K4: =I4*J4 -> 0.22 | L4: =((I4-K4)*Archetypes!$B$15)+(K4*Archetypes!$B$15*Archetypes!$B$22) -> 1.0044 | M4: =I4*Archetypes!$B$16 -> 7.5 | N4: =(IF(F4<0,Assumptions!$B$8,IF(F4<10,Assumptions!$B$34,IF(F4<25,Assumptions!$B$35,Assumptions!$B$36))))*((((Archetypes!$B$5*Assumptions!$B$4+Archetypes!$B$6*Assumptions!$B$5)*60))+(Assumptions!$B$6*(((Archetypes!$B$11*(IF(F4<0,1+Assumptions!$B$32*MIN(1,ABS(F4)/ABS(Assumptions!$B$21)),MAX(0.1,1-Assumptions!$B$31*(F4/50)))))-((Archetypes!$B$11*(IF(F4<0,1+Assumptions!$B$32*MIN(1,ABS(F4)/ABS(Assumptions!$B$21)),MAX(0.1,1-Assumptions!$B$31*(F4/50)))))*J4)*Archetypes!$B$20)+((Archetypes!$B$11*(IF(F4<0,1+Assumptions!$B$32*MIN(1,ABS(F4)/ABS(Assumptions!$B$21)),MAX(0.1,1-Assumptions!$B$31*(F4/50)))))*J4*Archetypes!$B$20*Archetypes!$B$21)*Assumptions!$B$18)*(IF($D4=1,1,Assumptions!$B$7)))+(((((Archetypes!$B$11*(IF(F4<0,1+Assumptions!$B$32*MIN(1,ABS(F4)/ABS(Assumptions!$B$21)),MAX(0.1,1-Assumptions!$B$31*(F4/50)))))-((Archetypes!$B$11*(IF(F4<0,1+Assumptions!$B$32*MIN(1,ABS(F4)/ABS(Assumptions!$B$21)),MAX(0.1,1-Assumptions!$B$31*(F4/50)))))*J4)*Archetypes!$B$15)*(Archetypes!$B$13*IF(F4<0,1-Assumptions!$B$33*MIN(1,ABS(F4)/ABS(Assumptions!$B$21)),1))*5)+(((Archetypes!$B$11*(IF(F4<0,1+Assumptions!$B$32*MIN(1,ABS(F4)/ABS(Assumptions!$B$21)),MAX(0.1,1-Assumptions!$B$31*(F4/50)))))*J4*Archetypes!$B$15*Archetypes!$B$22)*(Archetypes!$B$13*IF(F4<0,1-Assumptions!$B$33*MIN(1,ABS(F4)/ABS(Assumptions!$B$21)),1))*5*Assumptions!$B$18))*IF(F4<0,Assumptions!$B$9,1)))*$E4 -> 660.72 | O4: =(Archetypes!$B$7)+(N4)-(MAX(0,((Archetypes!$B$7)+(N4)-(P4)))*(IF(Archetypes!$B$27="",Assumptions!$B$11,Archetypes!$B$27))) -> 660.72 | P4: =Archetypes!$B$36 + (Assumptions!$B$67*(IF($E4=0,0,I4/$E4))*Assumptions!$B$71*(1+Assumptions!$B$68*(Archetypes!$B$14-1))) + (Assumptions!$B$69*Archetypes!$B$34*(IF($E4=0,0,I4/$E4))*Assumptions!$B$72*POWER(Assumptions!$B$70,Archetypes!$B$18-1)) -> 2476.56 | Q4: =MAX(0,(O4)-(P4)) -> 0 | S4: =Archetypes!$C$8 -> 5 | T4: =MAX(Assumptions!$B$21,S4+U4) -> 9.0601272 | U4: =((Y4*(Assumptions!$B$22+((Assumptions!$B$23-Assumptions!$B$22)*IF(V4>0,X4/V4,0)))*(1+Assumptions!$B$60*(Archetypes!$C$13-1)))+IF(Y4>V4,V4*Assumptions!$B$24,0)-IF(IF(V4>0,Z4/V4,1)<Assumptions!$B$61,((Z4*(Assumptions!$B$27*(1+Assumptions!$B$28*(Archetypes!$C$14-1))/(1+Assumptions!$B$29*(Archetypes!$C$12-1))))+(((V4*Archetypes!$C$17*IF(V4>0,Z4/V4,1)*Archetypes!$C$31)/100)*Assumptions!$B$30))*Assumptions!$B$62,((Z4*(Assumptions!$B$27*(1+Assumptions!$B$28*(Archetypes!$C$14-1))/(1+Assumptions!$B$29*(Archetypes!$C$12-1))))+(((V4*Archetypes!$C$17*IF(V4>0,Z4/V4,1)*Archetypes!$C$31)/100)*Assumptions!$B$30)))-(Assumptions!$B$25*Assumptions!$B$26*E4))*E4 -> 4.0601272 | V4: =(Archetypes!$C$11*(IF(S4<0,1+Assumptions!$B$32*MIN(1,ABS(S4)/ABS(Assumptions!$B$21)),MAX(0.1,1-Assumptions!$B$31*(S4/50)))))*$E4 -> 5.64 | W4: =Archetypes!$C$30 -> 0.038 | X4: =V4*W4 -> 0.21432 | Y4: =((V4-X4)*Archetypes!$C$15)+(X4*Archetypes!$C$15*Archetypes!$C$22) -> 2.852148 | Z4: =V4*Archetypes!$C$16 -> 2.538 | AA4: =(IF(S4<0,Assumptions!$B$8,IF(S4<10,Assumptions!$B$34,IF(S4<25,Assumptions!$B$35,Assumptions!$B$36))))*((((Archetypes!$C$5*Assumptions!$B$4+Archetypes!$C$6*Assumptions!$B$5)*60))+(Assumptions!$B$6*(((Archetypes!$C$11*(IF(S4<0,1+Assumptions!$B$32*MIN(1,ABS(S4)/ABS(Assumptions!$B$21)),MAX(0.1,1-Assumptions!$B$31*(S4/50)))))-((Archetypes!$C$11*(IF(S4<0,1+Assumptions!$B$32*MIN(1,ABS(S4)/ABS(Assumptions!$B$21)),MAX(0.1,1-Assumptions!$B$31*(S4/50)))))*W4)*Archetypes!$C$20)+((Archetypes!$C$11*(IF(S4<0,1+Assumptions!$B$32*MIN(1,ABS(S4)/ABS(Assumptions!$B$21)),MAX(0.1,1-Assumptions!$B$31*(S4/50)))))*W4*Archetypes!$C$20*Archetypes!$C$21)*Assumptions!$B$18)*(IF($D4=1,1,Assumptions!$B$7)))+(((((Archetypes!$C$11*(IF(S4<0,1+Assumptions!$B$32*MIN(1,ABS(S4)/ABS(Assumptions!$B$21)),MAX(0.1,1-Assumptions!$B$31*(S4/50)))))-((Archetypes!$C$11*(IF(S4<0,1+Assumptions!$B$32*MIN(1,ABS(S4)/ABS(Assumptions!$B$21)),MAX(0.1,1-Assumptions!$B$31*(S4/50)))))*W4)*Archetypes!$C$15)*(Archetypes!$C$13*IF(S4<0,1-Assumptions!$B$33*MIN(1,ABS(S4)/ABS(Assumptions!$B$21)),1))*5)+(((Archetypes!$C$11*(IF(S4<0,1+Assumptions!$B$32*MIN(1,ABS(S4)/ABS(Assumptions!$B$21)),MAX(0.1,1-Assumptions!$B$31*(S4/50)))))*W4*Archetypes!$C$15*Archetypes!$C$22)*(Archetypes!$C$13*IF(S4<0,1-Assumptions!$B$33*MIN(1,ABS(S4)/ABS(Assumptions!$B$21)),1))*5*Assumptions!$B$18))*IF(S4<0,Assumptions!$B$9,1)))*$E4 -> 1523.799 | AB4: =(Archetypes!$C$7)+(AA4)-(MAX(0,((Archetypes!$C$7)+(AA4)-(AC4)))*(IF(Archetypes!$C$27="",Assumptions!$B$11,Archetypes!$C$27))) -> 1523.799 | AC4: =Archetypes!$C$36 + (Assumptions!$B$67*(IF($E4=0,0,V4/$E4))*Assumptions!$B$71*(1+Assumptions!$B$68*(Archetypes!$C$14-1))) + (Assumptions!$B$69*Archetypes!$C$34*(IF($E4=0,0,V4/$E4))*Assumptions!$B$72*POWER(Assumptions!$B$70,Archetypes!$C$18-1)) -> 9561.96 | AD4: =MAX(0,(AB4)-(AC4)) -> 0 | AF4: =Archetypes!$D$8 -> 15 | AG4: =MAX(Assumptions!$B$21,AF4+AH4) -> 23.569261 | AH4: =((AL4*(Assumptions!$B$22+((Assumptions!$B$23-Assumptions!$B$22)*IF(AI4>0,AK4/AI4,0)))*(1+Assumptions!$B$60*(Archetypes!$D$13-1)))+IF(AL4>AI4,AI4*Assumptions!$B$24,0)-IF(IF(AI4>0,AM4/AI4,1)<Assumptions!$B$61,((AM4*(Assumptions!$B$27*(1+Assumptions!$B$28*(Archetypes!$D$14-1))/(1+Assumptions!$B$29*(Archetypes!$D$12-1))))+(((AI4*Archetypes!$D$17*IF(AI4>0,AM4/AI4,1)*Archetypes!$D$31)/100)*Assumptions!$B$30))*Assumptions!$B$62,((AM4*(Assumptions!$B$27*(1+Assumptions!$B$28*(Archetypes!$D$14-1))/(1+Assumptions!$B$29*(Archetypes!$D$12-1))))+(((AI4*Archetypes!$D$17*IF(AI4>0,AM4/AI4,1)*Archetypes!$D$31)/100)*Assumptions!$B$30)))-(Assumptions!$B$25*Assumptions!$B$26*E4))*E4 -> 8.5692608 | AI4: =(Archetypes!$D$11*(IF(AF4<0,1+Assumptions!$B$32*MIN(1,ABS(AF4)/ABS(Assumptions!$B$21)),MAX(0.1,1-Assumptions!$B$31*(AF4/50)))))*$E4 -> 2.46 | AJ4: =Archetypes!$D$30 -> 0.104 | AK4: =AI4*AJ4 -> 0.25584 | AL4: =((AI4-AK4)*Archetypes!$D$15)+(AK4*Archetypes!$D$15*Archetypes!$D$22) -> 3.843504 | AM4: =AI4*Archetypes!$D$16 -> 0.492 | AN4: =(IF(AF4<0,Assumptions!$B$8,IF(AF4<10,Assumptions!$B$34,IF(AF4<25,Assumptions!$B$35,Assumptions!$B$36))))*((((Archetypes!$D$5*Assumptions!$B$4+Archetypes!$D$6*Assumptions!$B$5)*60))+(Assumptions!$B$6*(((Archetypes!$D$11*(IF(AF4<0,1+Assumptions!$B$32*MIN(1,ABS(AF4)/ABS(Assumptions!$B$21)),MAX(0.1,1-Assumptions!$B$31*(AF4/50)))))-((Archetypes!$D$11*(IF(AF4<0,1+Assumptions!$B$32*MIN(1,ABS(AF4)/ABS(Assumptions!$B$21)),MAX(0.1,1-Assumptions!$B$31*(AF4/50)))))*AJ4)*Archetypes!$D$20)+((Archetypes!$D$11*(IF(AF4<0,1+Assumptions!$B$32*MIN(1,ABS(AF4)/ABS(Assumptions!$B$21)),MAX(0.1,1-Assumptions!$B$31*(AF4/50)))))*AJ4*Archetypes!$D$20*Archetypes!$D$21)*Assumptions!$B$18)*(IF($D4=1,1,Assumptions!$B$7)))+(((((Archetypes!$D$11*(IF(AF4<0,1+Assumptions!$B$32*MIN(1,ABS(AF4)/ABS(Assumptions!$B$21)),MAX(0.1,1-Assumptions!$B$31*(AF4/50)))))-((Archetypes!$D$11*(IF(AF4<0,1+Assumptions!$B$32*MIN(1,ABS(AF4)/ABS(Assumptions!$B$21)),MAX(0.1,1-Assumptions!$B$31*(AF4/50)))))*AJ4)*Archetypes!$D$15)*(Archetypes!$D$13*IF(AF4<0,1-Assumptions!$B$33*MIN(1,ABS(AF4)/ABS(Assumptions!$B$21)),1))*5)+(((Archetypes!$D$11*(IF(AF4<0,1+Assumptions!$B$32*MIN(1,ABS(AF4)/ABS(Assumptions!$B$21)),MAX(0.1,1-Assumptions!$B$31*(AF4/50)))))*AJ4*Archetypes!$D$15*Archetypes!$D$22)*(Archetypes!$D$13*IF(AF4<0,1-Assumptions!$B$33*MIN(1,ABS(AF4)/ABS(Assumptions!$B$21)),1))*5*Assumptions!$B$18))*IF(AF4<0,Assumptions!$B$9,1)))*$E4 -> 2505.8112 | AO4: =(Archetypes!$D$7)+(AN4)-(MAX(0,((Archetypes!$D$7)+(AN4)-(AP4)))*(IF(Archetypes!$D$27="",Assumptions!$B$11,Archetypes!$D$27))) -> 2505.8112 | AP4: =Archetypes!$D$36 + (Assumptions!$B$67*(IF($E4=0,0,AI4/$E4))*Assumptions!$B$71*(1+Assumptions!$B$68*(Archetypes!$D$14-1))) + (Assumptions!$B$69*Archetypes!$D$34*(IF($E4=0,0,AI4/$E4))*Assumptions!$B$72*POWER(Assumptions!$B$70,Archetypes!$D$18-1)) -> 21189.521 | AQ4: =MAX(0,(AO4)-(AP4)) -> 0
A5: 1 | B5: =INT(A5/24)+1 -> 1 | C5: =MOD(A5,24) -> 1 | D5: =IF(C5<Assumptions!$B$10,1,0) -> 1 | E5: 1 | F5: =G4 -> -2.0701216 | G5: =MAX(Assumptions!$B$21,F5+H5) -> -4.2462402 | H5: =((L5*(Assumptions!$B$22+((Assumptions!$B$23-Assumptions!$B$22)*IF(I5>0,K5/I5,0)))*(1+Assumptions!$B$60*(Archetypes!$B$13-1)))+IF(L5>I5,I5*Assumptions!$B$24,0)-IF(IF(I5>0,M5/I5,1)<Assumptions!$B$61,((M5*(Assumptions!$B$27*(1+Assumptions!$B$28*(Archetypes!$B$14-1))/(1+Assumptions!$B$29*(Archetypes!$B$12-1))))+(((I5*Archetypes!$B$17*IF(I5>0,M5/I5,1)*Archetypes!$B$31)/100)*Assumptions!$B$30))*Assumptions!$B$62,((M5*(Assumptions!$B$27*(1+Assumptions!$B$28*(Archetypes!$B$14-1))/(1+Assumptions!$B$29*(Archetypes!$B$12-1))))+(((I5*Archetypes!$B$17*IF(I5>0,M5/I5,1)*Archetypes!$B$31)/100)*Assumptions!$B$30)))-(Assumptions!$B$25*Assumptions!$B$26*E5))*E5 -> -2.1761186 | I5: =(Archetypes!$B$11*(IF(F5<0,1+Assumptions!$B$32*MIN(1,ABS(F5)/ABS(Assumptions!$B$21)),MAX(0.1,1-Assumptions!$B$31*(F5/50)))))*$E5 -> 10.552032 | J5: =Archetypes!$B$30 -> 0.022 | K5: =I5*J5 -> 0.23214471 | L5: =((I5-K5)*Archetypes!$B$15)+(K5*Archetypes!$B$15*Archetypes!$B$22) -> 1.0598461 | M5: =I5*Archetypes!$B$16 -> 7.9140243 | N5: =(IF(F5<0,Assumptions!$B$8,IF(F5<10,Assumptions!$B$34,IF(F5<25,Assumptions!$B$35,Assumptions!$B$36))))*((((Archetypes!$B$5*Assumptions!$B$4+Archetypes!$B$6*Assumptions!$B$5)*60))+(Assumptions!$B$6*(((Archetypes!$B$11*(IF(F5<0,1+Assumptions!$B$32*MIN(1,ABS(F5)/ABS(Assumptions!$B$21)),MAX(0.1,1-Assumptions!$B$31*(F5/50)))))-((Archetypes!$B$11*(IF(F5<0,1+Assumptions!$B$32*MIN(1,ABS(F5)/ABS(Assumptions!$B$21)),MAX(0.1,1-Assumptions!$B$31*(F5/50)))))*J5)*Archetypes!$B$20)+((Archetypes!$B$11*(IF(F5<0,1+Assumptions!$B$32*MIN(1,ABS(F5)/ABS(Assumptions!$B$21)),MAX(0.1,1-Assumptions!$B$31*(F5/50)))))*J5*Archetypes!$B$20*Archetypes!$B$21)*Assumptions!$B$18)*(IF($D5=1,1,Assumptions!$B$7)))+(((((Archetypes!$B$11*(IF(F5<0,1+Assumptions!$B$32*MIN(1,ABS(F5)/ABS(Assumptions!$B$21)),MAX(0.1,1-Assumptions!$B$31*(F5/50)))))-((Archetypes!$B$11*(IF(F5<0,1+Assumptions!$B$32*MIN(1,ABS(F5)/ABS(Assumptions!$B$21)),MAX(0.1,1-Assumptions!$B$31*(F5/50)))))*J5)*Archetypes!$B$15)*(Archetypes!$B$13*IF(F5<0,1-Assumptions!$B$33*MIN(1,ABS(F5)/ABS(Assumptions!$B$21)),1))*5)+(((Archetypes!$B$11*(IF(F5<0,1+Assumptions!$B$32*MIN(1,ABS(F5)/ABS(Assumptions!$B$21)),MAX(0.1,1-Assumptions!$B$31*(F5/50)))))*J5*Archetypes!$B$15*Archetypes!$B$22)*(Archetypes!$B$13*IF(F5<0,1-Assumptions!$B$33*MIN(1,ABS(F5)/ABS(Assumptions!$B$21)),1))*5*Assumptions!$B$18))*IF(F5<0,Assumptions!$B$9,1)))*$E5 -> 672.40906 | O5: =(O4)+(N5)-(MAX(0,((O4)+(N5)-(P5)))*(IF(Archetypes!$B$27="",Assumptions!$B$11,Archetypes!$B$27))) -> 1333.1291 | P5: =Archetypes!$B$36 + (Assumptions!$B$67*(IF($E5=0,0,I5/$E5))*Assumptions!$B$71*(1+Assumptions!$B$68*(Archetypes!$B$14-1))) + (Assumptions!$B$69*Archetypes!$B$34*(IF($E5=0,0,I5/$E5))*Assumptions!$B$72*POWER(Assumptions!$B$70,Archetypes!$B$18-1)) -> 2503.0576 | Q5: =MAX(0,(O5)-(P5)) -> 0 | S5: =T4 -> 9.0601272 | T5: =MAX(Assumptions!$B$21,S5+U5) -> 12.902038 | U5: =((Y5*(Assumptions!$B$22+((Assumptions!$B$23-Assumptions!$B$22)*IF(V5>0,X5/V5,0)))*(1+Assumptions!$B$60*(Archetypes!$C$13-1)))+IF(Y5>V5,V5*Assumptions!$B$24,0)-IF(IF(V5>0,Z5/V5,1)<Assumptions!$B$61,((Z5*(Assumptions!$B$27*(1+Assumptions!$B$28*(Archetypes!$C$14-1))/(1+Assumptions!$B$29*(Archetypes!$C$12-1))))+(((V5*Archetypes!$C$17*IF(V5>0,Z5/V5,1)*Archetypes!$C$31)/100)*Assumptions!$B$30))*Assumptions!$B$62,((Z5*(Assumptions!$B$27*(1+Assumptions!$B$28*(Archetypes!$C$14-1))/(1+Assumptions!$B$29*(Archetypes!$C$12-1))))+(((V5*Archetypes!$C$17*IF(V5>0,Z5/V5,1)*Archetypes!$C$31)/100)*Assumptions!$B$30)))-(Assumptions!$B$25*Assumptions!$B$26*E5))*E5 -> 3.8419104 | V5: =(Archetypes!$C$11*(IF(S5<0,1+Assumptions!$B$32*MIN(1,ABS(S5)/ABS(Assumptions!$B$21)),MAX(0.1,1-Assumptions!$B$31*(S5/50)))))*$E5 -> 5.3476708 | W5: =Archetypes!$C$30 -> 0.038 | X5: =V5*W5 -> 0.20321149 | Y5: =((V5-X5)*Archetypes!$C$15)+(X5*Archetypes!$C$15*Archetypes!$C$22) -> 2.7043171 | Z5: =V5*Archetypes!$C$16 -> 2.4064519 | AA5: =(IF(S5<0,Assumptions!$B$8,IF(S5<10,Assumptions!$B$34,IF(S5<25,Assumptions!$B$35,Assumptions!$B$36))))*((((Archetypes!$C$5*Assumptions!$B$4+Archetypes!$C$6*Assumptions!$B$5)*60))+(Assumptions!$B$6*(((Archetypes!$C$11*(IF(S5<0,1+Assumptions!$B$32*MIN(1,ABS(S5)/ABS(Assumptions!$B$21)),MAX(0.1,1-Assumptions!$B$31*(S5/50)))))-((Archetypes!$C$11*(IF(S5<0,1+Assumptions!$B$32*MIN(1,ABS(S5)/ABS(Assumptions!$B$21)),MAX(0.1,1-Assumptions!$B$31*(S5/50)))))*W5)*Archetypes!$C$20)+((Archetypes!$C$11*(IF(S5<0,1+Assumptions!$B$32*MIN(1,ABS(S5)/ABS(Assumptions!$B$21)),MAX(0.1,1-Assumptions!$B$31*(S5/50)))))*W5*Archetypes!$C$20*Archetypes!$C$21)*Assumptions!$B$18)*(IF($D5=1,1,Assumptions!$B$7)))+(((((Archetypes!$C$11*(IF(S5<0,1+Assumptions!$B$32*MIN(1,ABS(S5)/ABS(Assumptions!$B$21)),MAX(0.1,1-Assumptions!$B$31*(S5/50)))))-((Archetypes!$C$11*(IF(S5<0,1+Assumptions!$B$32*MIN(1,ABS(S5)/ABS(Assumptions!$B$21)),MAX(0.1,1-Assumptions!$B$31*(S5/50)))))*W5)*Archetypes!$C$15)*(Archetypes!$C$13*IF(S5<0,1-Assumptions!$B$33*MIN(1,ABS(S5)/ABS(Assumptions!$B$21)),1))*5)+(((Archetypes!$C$11*(IF(S5<0,1+Assumptions!$B$32*MIN(1,ABS(S5)/ABS(Assumptions!$B$21)),MAX(0.1,1-Assumptions!$B$31*(S5/50)))))*W5*Archetypes!$C$15*Archetypes!$C$22)*(Archetypes!$C$13*IF(S5<0,1-Assumptions!$B$33*MIN(1,ABS(S5)/ABS(Assumptions!$B$21)),1))*5*Assumptions!$B$18))*IF(S5<0,Assumptions!$B$9,1)))*$E5 -> 1477.4721 | AB5: =(AB4)+(AA5)-(MAX(0,((AB4)+(AA5)-(AC5)))*(IF(Archetypes!$C$27="",Assumptions!$B$11,Archetypes!$C$27))) -> 3001.2711 | AC5: =Archetypes!$C$36 + (Assumptions!$B$67*(IF($E5=0,0,V5/$E5))*Assumptions!$B$71*(1+Assumptions!$B$68*(Archetypes!$C$14-1))) + (Assumptions!$B$69*Archetypes!$C$34*(IF($E5=0,0,V5/$E5))*Assumptions!$B$72*POWER(Assumptions!$B$70,Archetypes!$C$18-1)) -> 9535.6504 | AD5: =MAX(0,(AB5)-(AC5)) -> 0 | AF5: =AG4 -> 23.569261 | AG5: =MAX(Assumptions!$B$21,AF5+AH5) -> 31.045093 | AH5: =((AL5*(Assumptions!$B$22+((Assumptions!$B$23-Assumptions!$B$22)*IF(AI5>0,AK5/AI5,0)))*(1+Assumptions!$B$60*(Archetypes!$D$13-1)))+IF(AL5>AI5,AI5*Assumptions!$B$24,0)-IF(IF(AI5>0,AM5/AI5,1)<Assumptions!$B$61,((AM5*(Assumptions!$B$27*(1+Assumptions!$B$28*(Archetypes!$D$14-1))/(1+Assumptions!$B$29*(Archetypes!$D$12-1))))+(((AI5*Archetypes!$D$17*IF(AI5>0,AM5/AI5,1)*Archetypes!$D$31)/100)*Assumptions!$B$30))*Assumptions!$B$62,((AM5*(Assumptions!$B$27*(1+Assumptions!$B$28*(Archetypes!$D$14-1))/(1+Assumptions!$B$29*(Archetypes!$D$12-1))))+(((AI5*Archetypes!$D$17*IF(AI5>0,AM5/AI5,1)*Archetypes!$D$31)/100)*Assumptions!$B$30)))-(Assumptions!$B$25*Assumptions!$B$26*E5))*E5 -> 7.4758322 | AI5: =(Archetypes!$D$11*(IF(AF5<0,1+Assumptions!$B$32*MIN(1,ABS(AF5)/ABS(Assumptions!$B$21)),MAX(0.1,1-Assumptions!$B$31*(AF5/50)))))*$E5 -> 2.1515066 | AJ5: =Archetypes!$D$30 -> 0.104 | AK5: =AI5*AJ5 -> 0.22375669 | AL5: =((AI5-AK5)*Archetypes!$D$15)+(AK5*Archetypes!$D$15*Archetypes!$D$22) -> 3.3615139 | AM5: =AI5*Archetypes!$D$16 -> 0.43030132 | AN5: =(IF(AF5<0,Assumptions!$B$8,IF(AF5<10,Assumptions!$B$34,IF(AF5<25,Assumptions!$B$35,Assumptions!$B$36))))*((((Archetypes!$D$5*Assumptions!$B$4+Archetypes!$D$6*Assumptions!$B$5)*60))+(Assumptions!$B$6*(((Archetypes!$D$11*(IF(AF5<0,1+Assumptions!$B$32*MIN(1,ABS(AF5)/ABS(Assumptions!$B$21)),MAX(0.1,1-Assumptions!$B$31*(AF5/50)))))-((Archetypes!$D$11*(IF(AF5<0,1+Assumptions!$B$32*MIN(1,ABS(AF5)/ABS(Assumptions!$B$21)),MAX(0.1,1-Assumptions!$B$31*(AF5/50)))))*AJ5)*Archetypes!$D$20)+((Archetypes!$D$11*(IF(AF5<0,1+Assumptions!$B$32*MIN(1,ABS(AF5)/ABS(Assumptions!$B$21)),MAX(0.1,1-Assumptions!$B$31*(AF5/50)))))*AJ5*Archetypes!$D$20*Archetypes!$D$21)*Assumptions!$B$18)*(IF($D5=1,1,Assumptions!$B$7)))+(((((Archetypes!$D$11*(IF(AF5<0,1+Assumptions!$B$32*MIN(1,ABS(AF5)/ABS(Assumptions!$B$21)),MAX(0.1,1-Assumptions!$B$31*(AF5/50)))))-((Archetypes!$D$11*(IF(AF5<0,1+Assumptions!$B$32*MIN(1,ABS(AF5)/ABS(Assumptions!$B$21)),MAX(0.1,1-Assumptions!$B$31*(AF5/50)))))*AJ5)*Archetypes!$D$15)*(Archetypes!$D$13*IF(AF5<0,1-Assumptions!$B$33*MIN(1,ABS(AF5)/ABS(Assumptions!$B$21)),1))*5)+(((Archetypes!$D$11*(IF(AF5<0,1+Assumptions!$B$32*MIN(1,ABS(AF5)/ABS(Assumptions!$B$21)),MAX(0.1,1-Assumptions!$B$31*(AF5/50)))))*AJ5*Archetypes!$D$15*Archetypes!$D$22)*(Archetypes!$D$13*IF(AF5<0,1-Assumptions!$B$33*MIN(1,ABS(AF5)/ABS(Assumptions!$B$21)),1))*5*Assumptions!$B$18))*IF(AF5<0,Assumptions!$B$9,1)))*$E5 -> 2313.0892 | AO5: =(AO4)+(AN5)-(MAX(0,((AO4)+(AN5)-(AP5)))*(IF(Archetypes!$D$27="",Assumptions!$B$11,Archetypes!$D$27))) -> 4818.9004 | AP5: =Archetypes!$D$36 + (Assumptions!$B$67*(IF($E5=0,0,AI5/$E5))*Assumptions!$B$71*(1+Assumptions!$B$68*(Archetypes!$D$14-1))) + (Assumptions!$B$69*Archetypes!$D$34*(IF($E5=0,0,AI5/$E5))*Assumptions!$B$72*POWER(Assumptions!$B$70,Archetypes!$D$18-1)) -> 21130.29 | AQ5: =MAX(0,(AO5)-(AP5)) -> 0
A6: 2 | B6: =INT(A6/24)+1 -> 1 | C6: =MOD(A6,24) -> 2 | D6: =IF(C6<Assumptions!$B$10,1,0) -> 0 | E6: 1 | F6: =G5 -> -4.2462402 | G6: =MAX(Assumptions!$B$21,F6+H6) -> -6.5337831 | H6: =((L6*(Assumptions!$B$22+((Assumptions!$B$23-Assumptions!$B$22)*IF(I6>0,K6/I6,0)))*(1+Assumptions!$B$60*(Archetypes!$B$13-1)))+IF(L6>I6,I6*Assumptions!$B$24,0)-IF(IF(I6>0,M6/I6,1)<Assumptions!$B$61,((M6*(Assumptions!$B$27*(1+Assumptions!$B$28*(Archetypes!$B$14-1))/(1+Assumptions!$B$29*(Archetypes!$B$12-1))))+(((I6*Archetypes!$B$17*IF(I6>0,M6/I6,1)*Archetypes!$B$31)/100)*Assumptions!$B$30))*Assumptions!$B$62,((M6*(Assumptions!$B$27*(1+Assumptions!$B$28*(Archetypes!$B$14-1))/(1+Assumptions!$B$29*(Archetypes!$B$12-1))))+(((I6*Archetypes!$B$17*IF(I6>0,M6/I6,1)*Archetypes!$B$31)/100)*Assumptions!$B$30)))-(Assumptions!$B$25*Assumptions!$B$26*E6))*E6 -> -2.2875429 | I6: =(Archetypes!$B$11*(IF(F6<0,1+Assumptions!$B$32*MIN(1,ABS(F6)/ABS(Assumptions!$B$21)),MAX(0.1,1-Assumptions!$B$31*(F6/50)))))*$E6 -> 11.132331 | J6: =Archetypes!$B$30 -> 0.022 | K6: =I6*J6 -> 0.24491128 | L6: =((I6-K6)*Archetypes!$B$15)+(K6*Archetypes!$B$15*Archetypes!$B$22) -> 1.1181313 | M6: =I6*Archetypes!$B$16 -> 8.349248 | N6: =(IF(F6<0,Assumptions!$B$8,IF(F6<10,Assumptions!$B$34,IF(F6<25,Assumptions!$B$35,Assumptions!$B$36))))*((((Archetypes!$B$5*Assumptions!$B$4+Archetypes!$B$6*Assumptions!$B$5)*60))+(Assumptions!$B$6*(((Archetypes!$B$11*(IF(F6<0,1+Assumptions!$B$32*MIN(1,ABS(F6)/ABS(Assumptions!$B$21)),MAX(0.1,1-Assumptions!$B$31*(F6/50)))))-((Archetypes!$B$11*(IF(F6<0,1+Assumptions!$B$32*MIN(1,ABS(F6)/ABS(Assumptions!$B$21)),MAX(0.1,1-Assumptions!$B$31*(F6/50)))))*J6)*Archetypes!$B$20)+((Archetypes!$B$11*(IF(F6<0,1+Assumptions!$B$32*MIN(1,ABS(F6)/ABS(Assumptions!$B$21)),MAX(0.1,1-Assumptions!$B$31*(F6/50)))))*J6*Archetypes!$B$20*Archetypes!$B$21)*Assumptions!$B$18)*(IF($D6=1,1,Assumptions!$B$7)))+(((((Archetypes!$B$11*(IF(F6<0,1+Assumptions!$B$32*MIN(1,ABS(F6)/ABS(Assumptions!$B$21)),MAX(0.1,1-Assumptions!$B$31*(F6/50)))))-((Archetypes!$B$11*(IF(F6<0,1+Assumptions!$B$32*MIN(1,ABS(F6)/ABS(Assumptions!$B$21)),MAX(0.1,1-Assumptions!$B$31*(F6/50)))))*J6)*Archetypes!$B$15)*(Archetypes!$B$13*IF(F6<0,1-Assumptions!$B$33*MIN(1,ABS(F6)/ABS(Assumptions!$B$21)),1))*5)+(((Archetypes!$B$11*(IF(F6<0,1+Assumptions!$B$32*MIN(1,ABS(F6)/ABS(Assumptions!$B$21)),MAX(0.1,1-Assumptions!$B$31*(F6/50)))))*J6*Archetypes!$B$15*Archetypes!$B$22)*(Archetypes!$B$13*IF(F6<0,1-Assumptions!$B$33*MIN(1,ABS(F6)/ABS(Assumptions!$B$21)),1))*5*Assumptions!$B$18))*IF(F6<0,Assumptions!$B$9,1)))*$E6 -> 503.6884 | O6: =(O5)+(N6)-(MAX(0,((O5)+(N6)-(P6)))*(IF(Archetypes!$B$27="",Assumptions!$B$11,Archetypes!$B$27))) -> 1836.8175 | P6: =Archetypes!$B$36 + (Assumptions!$B$67*(IF($E6=0,0,I6/$E6))*Assumptions!$B$71*(1+Assumptions!$B$68*(Archetypes!$B$14-1))) + (Assumptions!$B$69*Archetypes!$B$34*(IF($E6=0,0,I6/$E6))*Assumptions!$B$72*POWER(Assumptions!$B$70,Archetypes!$B$18-1)) -> 2530.9119 | Q6: =MAX(0,(O6)-(P6)) -> 0 | S6: =T5 -> 12.902038 | T6: =MAX(Assumptions!$B$21,S6+U6) -> 16.53746 | U6: =((Y6*(Assumptions!$B$22+((Assumptions!$B$23-Assumptions!$B$22)*IF(V6>0,X6/V6,0)))*(1+Assumptions!$B$60*(Archetypes!$C$13-1)))+IF(Y6>V6,V6*Assumptions!$B$24,0)-IF(IF(V6>0,Z6/V6,1)<Assumptions!$B$61,((Z6*(Assumptions!$B$27*(1+Assumptions!$B$28*(Archetypes!$C$14-1))/(1+Assumptions!$B$29*(Archetypes!$C$12-1))))+(((V6*Archetypes!$C$17*IF(V6>0,Z6/V6,1)*Archetypes!$C$31)/100)*Assumptions!$B$30))*Assumptions!$B$62,((Z6*(Assumptions!$B$27*(1+Assumptions!$B$28*(Archetypes!$C$14-1))/(1+Assumptions!$B$29*(Archetypes!$C$12-1))))+(((V6*Archetypes!$C$17*IF(V6>0,Z6/V6,1)*Archetypes!$C$31)/100)*Assumptions!$B$30)))-(Assumptions!$B$25*Assumptions!$B$26*E6))*E6 -> 3.6354219 | V6: =(Archetypes!$C$11*(IF(S6<0,1+Assumptions!$B$32*MIN(1,ABS(S6)/ABS(Assumptions!$B$21)),MAX(0.1,1-Assumptions!$B$31*(S6/50)))))*$E6 -> 5.0710533 | W6: =Archetypes!$C$30 -> 0.038 | X6: =V6*W6 -> 0.19270003 | Y6: =((V6-X6)*Archetypes!$C$15)+(X6*Archetypes!$C$15*Archetypes!$C$22) -> 2.5644316 | Z6: =V6*Archetypes!$C$16 -> 2.281974 | AA6: =(IF(S6<0,Assumptions!$B$8,IF(S6<10,Assumptions!$B$34,IF(S6<25,Assumptions!$B$35,Assumptions!$B$36))))*((((Archetypes!$C$5*Assumptions!$B$4+Archetypes!$C$6*Assumptions!$B$5)*60))+(Assumptions!$B$6*(((Archetypes!$C$11*(IF(S6<0,1+Assumptions!$B$32*MIN(1,ABS(S6)/ABS(Assumptions!$B$21)),MAX(0.1,1-Assumptions!$B$31*(S6/50)))))-((Archetypes!$C$11*(IF(S6<0,1+Assumptions!$B$32*MIN(1,ABS(S6)/ABS(Assumptions!$B$21)),MAX(0.1,1-Assumptions!$B$31*(S6/50)))))*W6)*Archetypes!$C$20)+((Archetypes!$C$11*(IF(S6<0,1+Assumptions!$B$32*MIN(1,ABS(S6)/ABS(Assumptions!$B$21)),MAX(0.1,1-Assumptions!$B$31*(S6/50)))))*W6*Archetypes!$C$20*Archetypes!$C$21)*Assumptions!$B$18)*(IF($D6=1,1,Assumptions!$B$7)))+(((((Archetypes!$C$11*(IF(S6<0,1+Assumptions!$B$32*MIN(1,ABS(S6)/ABS(Assumptions!$B$21)),MAX(0.1,1-Assumptions!$B$31*(S6/50)))))-((Archetypes!$C$11*(IF(S6<0,1+Assumptions!$B$32*MIN(1,ABS(S6)/ABS(Assumptions!$B$21)),MAX(0.1,1-Assumptions!$B$31*(S6/50)))))*W6)*Archetypes!$C$15)*(Archetypes!$C$13*IF(S6<0,1-Assumptions!$B$33*MIN(1,ABS(S6)/ABS(Assumptions!$B$21)),1))*5)+(((Archetypes!$C$11*(IF(S6<0,1+Assumptions!$B$32*MIN(1,ABS(S6)/ABS(Assumptions!$B$21)),MAX(0.1,1-Assumptions!$B$31*(S6/50)))))*W6*Archetypes!$C$15*Archetypes!$C$22)*(Archetypes!$C$13*IF(S6<0,1-Assumptions!$B$33*MIN(1,ABS(S6)/ABS(Assumptions!$B$21)),1))*5*Assumptions!$B$18))*IF(S6<0,Assumptions!$B$9,1)))*$E6 -> 1038.5209 | AB6: =(AB5)+(AA6)-(MAX(0,((AB5)+(AA6)-(AC6)))*(IF(Archetypes!$C$27="",Assumptions!$B$11,Archetypes!$C$27))) -> 4039.792 | AC6: =Archetypes!$C$36 + (Assumptions!$B$67*(IF($E6=0,0,V6/$E6))*Assumptions!$B$71*(1+Assumptions!$B$68*(Archetypes!$C$14-1))) + (Assumptions!$B$69*Archetypes!$C$34*(IF($E6=0,0,V6/$E6))*Assumptions!$B$72*POWER(Assumptions!$B$70,Archetypes!$C$18-1)) -> 9510.7548 | AD6: =MAX(0,(AB6)-(AC6)) -> 0 | AF6: =AG5 -> 31.045093 | AG6: =MAX(Assumptions!$B$21,AF6+AH6) -> 37.567017 | AH6: =((AL6*(Assumptions!$B$22+((Assumptions!$B$23-Assumptions!$B$22)*IF(AI6>0,AK6/AI6,0)))*(1+Assumptions!$B$60*(Archetypes!$D$13-1)))+IF(AL6>AI6,AI6*Assumptions!$B$24,0)-IF(IF(AI6>0,AM6/AI6,1)<Assumptions!$B$61,((AM6*(Assumptions!$B$27*(1+Assumptions!$B$28*(Archetypes!$D$14-1))/(1+Assumptions!$B$29*(Archetypes!$D$12-1))))+(((AI6*Archetypes!$D$17*IF(AI6>0,AM6/AI6,1)*Archetypes!$D$31)/100)*Assumptions!$B$30))*Assumptions!$B$62,((AM6*(Assumptions!$B$27*(1+Assumptions!$B$28*(Archetypes!$D$14-1))/(1+Assumptions!$B$29*(Archetypes!$D$12-1))))+(((AI6*Archetypes!$D$17*IF(AI6>0,AM6/AI6,1)*Archetypes!$D$31)/100)*Assumptions!$B$30)))-(Assumptions!$B$25*Assumptions!$B$26*E6))*E6 -> 6.5219239 | AI6: =(Archetypes!$D$11*(IF(AF6<0,1+Assumptions!$B$32*MIN(1,ABS(AF6)/ABS(Assumptions!$B$21)),MAX(0.1,1-Assumptions!$B$31*(AF6/50)))))*$E6 -> 1.8823767 | AJ6: =Archetypes!$D$30 -> 0.104 | AK6: =AI6*AJ6 -> 0.19576717 | AL6: =((AI6-AK6)*Archetypes!$D$15)+(AK6*Archetypes!$D$15*Archetypes!$D$22) -> 2.9410253 | AM6: =AI6*Archetypes!$D$16 -> 0.37647533 | AN6: =(IF(AF6<0,Assumptions!$B$8,IF(AF6<10,Assumptions!$B$34,IF(AF6<25,Assumptions!$B$35,Assumptions!$B$36))))*((((Archetypes!$D$5*Assumptions!$B$4+Archetypes!$D$6*Assumptions!$B$5)*60))+(Assumptions!$B$6*(((Archetypes!$D$11*(IF(AF6<0,1+Assumptions!$B$32*MIN(1,ABS(AF6)/ABS(Assumptions!$B$21)),MAX(0.1,1-Assumptions!$B$31*(AF6/50)))))-((Archetypes!$D$11*(IF(AF6<0,1+Assumptions!$B$32*MIN(1,ABS(AF6)/ABS(Assumptions!$B$21)),MAX(0.1,1-Assumptions!$B$31*(AF6/50)))))*AJ6)*Archetypes!$D$20)+((Archetypes!$D$11*(IF(AF6<0,1+Assumptions!$B$32*MIN(1,ABS(AF6)/ABS(Assumptions!$B$21)),MAX(0.1,1-Assumptions!$B$31*(AF6/50)))))*AJ6*Archetypes!$D$20*Archetypes!$D$21)*Assumptions!$B$18)*(IF($D6=1,1,Assumptions!$B$7)))+(((((Archetypes!$D$11*(IF(AF6<0,1+Assumptions!$B$32*MIN(1,ABS(AF6)/ABS(Assumptions!$B$21)),MAX(0.1,1-Assumptions!$B$31*(AF6/50)))))-((Archetypes!$D$11*(IF(AF6<0,1+Assumptions!$B$32*MIN(1,ABS(AF6)/ABS(Assumptions!$B$21)),MAX(0.1,1-Assumptions!$B$31*(AF6/50)))))*AJ6)*Archetypes!$D$15)*(Archetypes!$D$13*IF(AF6<0,1-Assumptions!$B$33*MIN(1,ABS(AF6)/ABS(Assumptions!$B$21)),1))*5)+(((Archetypes!$D$11*(IF(AF6<0,1+Assumptions!$B$32*MIN(1,ABS(AF6)/ABS(Assumptions!$B$21)),MAX(0.1,1-Assumptions!$B$31*(AF6/50)))))*AJ6*Archetypes!$D$15*Archetypes!$D$22)*(Archetypes!$D$13*IF(AF6<0,1-Assumptions!$B$33*MIN(1,ABS(AF6)/ABS(Assumptions!$B$21)),1))*5*Assumptions!$B$18))*IF(AF6<0,Assumptions!$B$9,1)))*$E6 -> 1322.7657 | AO6: =(AO5)+(AN6)-(MAX(0,((AO5)+(AN6)-(AP6)))*(IF(Archetypes!$D$27="",Assumptions!$B$11,Archetypes!$D$27))) -> 6141.6662 | AP6: =Archetypes!$D$36 + (Assumptions!$B$67*(IF($E6=0,0,AI6/$E6))*Assumptions!$B$71*(1+Assumptions!$B$68*(Archetypes!$D$14-1))) + (Assumptions!$B$69*Archetypes!$D$34*(IF($E6=0,0,AI6/$E6))*Assumptions!$B$72*POWER(Assumptions!$B$70,Archetypes!$D$18-1)) -> 21078.617 | AQ6: =MAX(0,(AO6)-(AP6)) -> 0
A7: 3 | B7: =INT(A7/24)+1 -> 1 | C7: =MOD(A7,24) -> 3 | D7: =IF(C7<Assumptions!$B$10,1,0) -> 0 | E7: 1 | F7: =G6 -> -6.5337831 | G7: =MAX(Assumptions!$B$21,F7+H7) -> -8.9384556 | H7: =((L7*(Assumptions!$B$22+((Assumptions!$B$23-Assumptions!$B$22)*IF(I7>0,K7/I7,0)))*(1+Assumptions!$B$60*(Archetypes!$B$13-1)))+IF(L7>I7,I7*Assumptions!$B$24,0)-IF(IF(I7>0,M7/I7,1)<Assumptions!$B$61,((M7*(Assumptions!$B$27*(1+Assumptions!$B$28*(Archetypes!$B$14-1))/(1+Assumptions!$B$29*(Archetypes!$B$12-1))))+(((I7*Archetypes!$B$17*IF(I7>0,M7/I7,1)*Archetypes!$B$31)/100)*Assumptions!$B$30))*Assumptions!$B$62,((M7*(Assumptions!$B$27*(1+Assumptions!$B$28*(Archetypes!$B$14-1))/(1+Assumptions!$B$29*(Archetypes!$B$12-1))))+(((I7*Archetypes!$B$17*IF(I7>0,M7/I7,1)*Archetypes!$B$31)/100)*Assumptions!$B$30)))-(Assumptions!$B$25*Assumptions!$B$26*E7))*E7 -> -2.4046725 | I7: =(Archetypes!$B$11*(IF(F7<0,1+Assumptions!$B$32*MIN(1,ABS(F7)/ABS(Assumptions!$B$21)),MAX(0.1,1-Assumptions!$B$31*(F7/50)))))*$E7 -> 11.742342 | J7: =Archetypes!$B$30 -> 0.022 | K7: =I7*J7 -> 0.25833153 | L7: =((I7-K7)*Archetypes!$B$15)+(K7*Archetypes!$B$15*Archetypes!$B$22) -> 1.1794008 | M7: =I7*Archetypes!$B$16 -> 8.8067566 | N7: =(IF(F7<0,Assumptions!$B$8,IF(F7<10,Assumptions!$B$34,IF(F7<25,Assumptions!$B$35,Assumptions!$B$36))))*((((Archetypes!$B$5*Assumptions!$B$4+Archetypes!$B$6*Assumptions!$B$5)*60))+(Assumptions!$B$6*(((Archetypes!$B$11*(IF(F7<0,1+Assumptions!$B$32*MIN(1,ABS(F7)/ABS(Assumptions!$B$21)),MAX(0.1,1-Assumptions!$B$31*(F7/50)))))-((Archetypes!$B$11*(IF(F7<0,1+Assumptions!$B$32*MIN(1,ABS(F7)/ABS(Assumptions!$B$21)),MAX(0.1,1-Assumptions!$B$31*(F7/50)))))*J7)*Archetypes!$B$20)+((Archetypes!$B$11*(IF(F7<0,1+Assumptions!$B$32*MIN(1,ABS(F7)/ABS(Assumptions!$B$21)),MAX(0.1,1-Assumptions!$B$31*(F7/50)))))*J7*Archetypes!$B$20*Archetypes!$B$21)*Assumptions!$B$18)*(IF($D7=1,1,Assumptions!$B$7)))+(((((Archetypes!$B$11*(IF(F7<0,1+Assumptions!$B$32*MIN(1,ABS(F7)/ABS(Assumptions!$B$21)),MAX(0.1,1-Assumptions!$B$31*(F7/50)))))-((Archetypes!$B$11*(IF(F7<0,1+Assumptions!$B$32*MIN(1,ABS(F7)/ABS(Assumptions!$B$21)),MAX(0.1,1-Assumptions!$B$31*(F7/50)))))*J7)*Archetypes!$B$15)*(Archetypes!$B$13*IF(F7<0,1-Assumptions!$B$33*MIN(1,ABS(F7)/ABS(Assumptions!$B$21)),1))*5)+(((Archetypes!$B$11*(IF(F7<0,1+Assumptions!$B$32*MIN(1,ABS(F7)/ABS(Assumptions!$B$21)),MAX(0.1,1-Assumptions!$B$31*(F7/50)))))*J7*Archetypes!$B$15*Archetypes!$B$22)*(Archetypes!$B$13*IF(F7<0,1-Assumptions!$B$33*MIN(1,ABS(F7)/ABS(Assumptions!$B$21)),1))*5*Assumptions!$B$18))*IF(F7<0,Assumptions!$B$9,1)))*$E7 -> 503.25387 | O7: =(O6)+(N7)-(MAX(0,((O6)+(N7)-(P7)))*(IF(Archetypes!$B$27="",Assumptions!$B$11,Archetypes!$B$27))) -> 2340.0713 | P7: =Archetypes!$B$36 + (Assumptions!$B$67*(IF($E7=0,0,I7/$E7))*Assumptions!$B$71*(1+Assumptions!$B$68*(Archetypes!$B$14-1))) + (Assumptions!$B$69*Archetypes!$B$34*(IF($E7=0,0,I7/$E7))*Assumptions!$B$72*POWER(Assumptions!$B$70,Archetypes!$B$18-1)) -> 2560.1924 | Q7: =MAX(0,(O7)-(P7)) -> 0 | S7: =T6 -> 16.53746 | T7: =MAX(Assumptions!$B$21,S7+U7) -> 19.977491 | U7: =((Y7*(Assumptions!$B$22+((Assumptions!$B$23-Assumptions!$B$22)*IF(V7>0,X7/V7,0)))*(1+Assumptions!$B$60*(Archetypes!$C$13-1)))+IF(Y7>V7,V7*Assumptions!$B$24,0)-IF(IF(V7>0,Z7/V7,1)<Assumptions!$B$61,((Z7*(Assumptions!$B$27*(1+Assumptions!$B$28*(Archetypes!$C$14-1))/(1+Assumptions!$B$29*(Archetypes!$C$12-1))))+(((V7*Archetypes!$C$17*IF(V7>0,Z7/V7,1)*Archetypes!$C$31)/100)*Assumptions!$B$30))*Assumptions!$B$62,((Z7*(Assumptions!$B$27*(1+Assumptions!$B$28*(Archetypes!$C$14-1))/(1+Assumptions!$B$29*(Archetypes!$C$12-1))))+(((V7*Archetypes!$C$17*IF(V7>0,Z7/V7,1)*Archetypes!$C$31)/100)*Assumptions!$B$30)))-(Assumptions!$B$25*Assumptions!$B$26*E7))*E7 -> 3.4400314 | V7: =(Archetypes!$C$11*(IF(S7<0,1+Assumptions!$B$32*MIN(1,ABS(S7)/ABS(Assumptions!$B$21)),MAX(0.1,1-Assumptions!$B$31*(S7/50)))))*$E7 -> 4.8093029 | W7: =Archetypes!$C$30 -> 0.038 | X7: =V7*W7 -> 0.18275351 | Y7: =((V7-X7)*Archetypes!$C$15)+(X7*Archetypes!$C$15*Archetypes!$C$22) -> 2.4320645 | Z7: =V7*Archetypes!$C$16 -> 2.1641863 | AA7: =(IF(S7<0,Assumptions!$B$8,IF(S7<10,Assumptions!$B$34,IF(S7<25,Assumptions!$B$35,Assumptions!$B$36))))*((((Archetypes!$C$5*Assumptions!$B$4+Archetypes!$C$6*Assumptions!$B$5)*60))+(Assumptions!$B$6*(((Archetypes!$C$11*(IF(S7<0,1+Assumptions!$B$32*MIN(1,ABS(S7)/ABS(Assumptions!$B$21)),MAX(0.1,1-Assumptions!$B$31*(S7/50)))))-((Archetypes!$C$11*(IF(S7<0,1+Assumptions!$B$32*MIN(1,ABS(S7)/ABS(Assumptions!$B$21)),MAX(0.1,1-Assumptions!$B$31*(S7/50)))))*W7)*Archetypes!$C$20)+((Archetypes!$C$11*(IF(S7<0,1+Assumptions!$B$32*MIN(1,ABS(S7)/ABS(Assumptions!$B$21)),MAX(0.1,1-Assumptions!$B$31*(S7/50)))))*W7*Archetypes!$C$20*Archetypes!$C$21)*Assumptions!$B$18)*(IF($D7=1,1,Assumptions!$B$7)))+(((((Archetypes!$C$11*(IF(S7<0,1+Assumptions!$B$32*MIN(1,ABS(S7)/ABS(Assumptions!$B$21)),MAX(0.1,1-Assumptions!$B$31*(S7/50)))))-((Archetypes!$C$11*(IF(S7<0,1+Assumptions!$B$32*MIN(1,ABS(S7)/ABS(Assumptions!$B$21)),MAX(0.1,1-Assumptions!$B$31*(S7/50)))))*W7)*Archetypes!$C$15)*(Archetypes!$C$13*IF(S7<0,1-Assumptions!$B$33*MIN(1,ABS(S7)/ABS(Assumptions!$B$21)),1))*5)+(((Archetypes!$C$11*(IF(S7<0,1+Assumptions!$B$32*MIN(1,ABS(S7)/ABS(Assumptions!$B$21)),MAX(0.1,1-Assumptions!$B$31*(S7/50)))))*W7*Archetypes!$C$15*Archetypes!$C$22)*(Archetypes!$C$13*IF(S7<0,1-Assumptions!$B$33*MIN(1,ABS(S7)/ABS(Assumptions!$B$21)),1))*5*Assumptions!$B$18))*IF(S7<0,Assumptions!$B$9,1)))*$E7 -> 1015.8085 | AB7: =(AB6)+(AA7)-(MAX(0,((AB6)+(AA7)-(AC7)))*(IF(Archetypes!$C$27="",Assumptions!$B$11,Archetypes!$C$27))) -> 5055.6005 | AC7: =Archetypes!$C$36 + (Assumptions!$B$67*(IF($E7=0,0,V7/$E7))*Assumptions!$B$71*(1+Assumptions!$B$68*(Archetypes!$C$14-1))) + (Assumptions!$B$69*Archetypes!$C$34*(IF($E7=0,0,V7/$E7))*Assumptions!$B$72*POWER(Assumptions!$B$70,Archetypes!$C$18-1)) -> 9487.1973 | AD7: =MAX(0,(AB7)-(AC7)) -> 0 | AF7: =AG6 -> 37.567017 | AG7: =MAX(Assumptions!$B$21,AF7+AH7) -> 43.25675 | AH7: =((AL7*(Assumptions!$B$22+((Assumptions!$B$23-Assumptions!$B$22)*IF(AI7>0,AK7/AI7,0)))*(1+Assumptions!$B$60*(Archetypes!$D$13-1)))+IF(AL7>AI7,AI7*Assumptions!$B$24,0)-IF(IF(AI7>0,AM7/AI7,1)<Assumptions!$B$61,((AM7*(Assumptions!$B$27*(1+Assumptions!$B$28*(Archetypes!$D$14-1))/(1+Assumptions!$B$29*(Archetypes!$D$12-1))))+(((AI7*Archetypes!$D$17*IF(AI7>0,AM7/AI7,1)*Archetypes!$D$31)/100)*Assumptions!$B$30))*Assumptions!$B$62,((AM7*(Assumptions!$B$27*(1+Assumptions!$B$28*(Archetypes!$D$14-1))/(1+Assumptions!$B$29*(Archetypes!$D$12-1))))+(((AI7*Archetypes!$D$17*IF(AI7>0,AM7/AI7,1)*Archetypes!$D$31)/100)*Assumptions!$B$30)))-(Assumptions!$B$25*Assumptions!$B$26*E7))*E7 -> 5.6897334 | AI7: =(Archetypes!$D$11*(IF(AF7<0,1+Assumptions!$B$32*MIN(1,ABS(AF7)/ABS(Assumptions!$B$21)),MAX(0.1,1-Assumptions!$B$31*(AF7/50)))))*$E7 -> 1.6475874 | AJ7: =Archetypes!$D$30 -> 0.104 | AK7: =AI7*AJ7 -> 0.17134909 | AL7: =((AI7-AK7)*Archetypes!$D$15)+(AK7*Archetypes!$D$15*Archetypes!$D$22) -> 2.5741905 | AM7: =AI7*Archetypes!$D$16 -> 0.32951748 | AN7: =(IF(AF7<0,Assumptions!$B$8,IF(AF7<10,Assumptions!$B$34,IF(AF7<25,Assumptions!$B$35,Assumptions!$B$36))))*((((Archetypes!$D$5*Assumptions!$B$4+Archetypes!$D$6*Assumptions!$B$5)*60))+(Assumptions!$B$6*(((Archetypes!$D$11*(IF(AF7<0,1+Assumptions!$B$32*MIN(1,ABS(AF7)/ABS(Assumptions!$B$21)),MAX(0.1,1-Assumptions!$B$31*(AF7/50)))))-((Archetypes!$D$11*(IF(AF7<0,1+Assumptions!$B$32*MIN(1,ABS(AF7)/ABS(Assumptions!$B$21)),MAX(0.1,1-Assumptions!$B$31*(AF7/50)))))*AJ7)*Archetypes!$D$20)+((Archetypes!$D$11*(IF(AF7<0,1+Assumptions!$B$32*MIN(1,ABS(AF7)/ABS(Assumptions!$B$21)),MAX(0.1,1-Assumptions!$B$31*(AF7/50)))))*AJ7*Archetypes!$D$20*Archetypes!$D$21)*Assumptions!$B$18)*(IF($D7=1,1,Assumptions!$B$7)))+(((((Archetypes!$D$11*(IF(AF7<0,1+Assumptions!$B$32*MIN(1,ABS(AF7)/ABS(Assumptions!$B$21)),MAX(0.1,1-Assumptions!$B$31*(AF7/50)))))-((Archetypes!$D$11*(IF(AF7<0,1+Assumptions!$B$32*MIN(1,ABS(AF7)/ABS(Assumptions!$B$21)),MAX(0.1,1-Assumptions!$B$31*(AF7/50)))))*AJ7)*Archetypes!$D$15)*(Archetypes!$D$13*IF(AF7<0,1-Assumptions!$B$33*MIN(1,ABS(AF7)/ABS(Assumptions!$B$21)),1))*5)+(((Archetypes!$D$11*(IF(AF7<0,1+Assumptions!$B$32*MIN(1,ABS(AF7)/ABS(Assumptions!$B$21)),MAX(0.1,1-Assumptions!$B$31*(AF7/50)))))*AJ7*Archetypes!$D$15*Archetypes!$D$22)*(Archetypes!$D$13*IF(AF7<0,1-Assumptions!$B$33*MIN(1,ABS(AF7)/ABS(Assumptions!$B$21)),1))*5*Assumptions!$B$18))*IF(AF7<0,Assumptions!$B$9,1)))*$E7 -> 1265.918 | AO7: =(AO6)+(AN7)-(MAX(0,((AO6)+(AN7)-(AP7)))*(IF(Archetypes!$D$27="",Assumptions!$B$11,Archetypes!$D$27))) -> 7407.5841 | AP7: =Archetypes!$D$36 + (Assumptions!$B$67*(IF($E7=0,0,AI7/$E7))*Assumptions!$B$71*(1+Assumptions!$B$68*(Archetypes!$D$14-1))) + (Assumptions!$B$69*Archetypes!$D$34*(IF($E7=0,0,AI7/$E7))*Assumptions!$B$72*POWER(Assumptions!$B$70,Archetypes!$D$18-1)) -> 21033.537 | AQ7: =MAX(0,(AO7)-(AP7)) -> 0
A8: 4 | B8: =INT(A8/24)+1 -> 1 | C8: =MOD(A8,24) -> 4 | D8: =IF(C8<Assumptions!$B$10,1,0) -> 0 | E8: 1 | F8: =G7 -> -8.9384556 | G8: =MAX(Assumptions!$B$21,F8+H8) -> -11.466255 | H8: =((L8*(Assumptions!$B$22+((Assumptions!$B$23-Assumptions!$B$22)*IF(I8>0,K8/I8,0)))*(1+Assumptions!$B$60*(Archetypes!$B$13-1)))+IF(L8>I8,I8*Assumptions!$B$24,0)-IF(IF(I8>0,M8/I8,1)<Assumptions!$B$61,((M8*(Assumptions!$B$27*(1+Assumptions!$B$28*(Archetypes!$B$14-1))/(1+Assumptions!$B$29*(Archetypes!$B$12-1))))+(((I8*Archetypes!$B$17*IF(I8>0,M8/I8,1)*Archetypes!$B$31)/100)*Assumptions!$B$30))*Assumptions!$B$62,((M8*(Assumptions!$B$27*(1+Assumptions!$B$28*(Archetypes!$B$14-1))/(1+Assumptions!$B$29*(Archetypes!$B$12-1))))+(((I8*Archetypes!$B$17*IF(I8>0,M8/I8,1)*Archetypes!$B$31)/100)*Assumptions!$B$30)))-(Assumptions!$B$25*Assumptions!$B$26*E8))*E8 -> -2.5277996 | I8: =(Archetypes!$B$11*(IF(F8<0,1+Assumptions!$B$32*MIN(1,ABS(F8)/ABS(Assumptions!$B$21)),MAX(0.1,1-Assumptions!$B$31*(F8/50)))))*$E8 -> 12.383588 | J8: =Archetypes!$B$30 -> 0.022 | K8: =I8*J8 -> 0.27243894 | L8: =((I8-K8)*Archetypes!$B$15)+(K8*Archetypes!$B$15*Archetypes!$B$22) -> 1.2438076 | M8: =I8*Archetypes!$B$16 -> 9.2876911 | N8: =(IF(F8<0,Assumptions!$B$8,IF(F8<10,Assumptions!$B$34,IF(F8<25,Assumptions!$B$35,Assumptions!$B$36))))*((((Archetypes!$B$5*Assumptions!$B$4+Archetypes!$B$6*Assumptions!$B$5)*60))+(Assumptions!$B$6*(((Archetypes!$B$11*(IF(F8<0,1+Assumptions!$B$32*MIN(1,ABS(F8)/ABS(Assumptions!$B$21)),MAX(0.1,1-Assumptions!$B$31*(F8/50)))))-((Archetypes!$B$11*(IF(F8<0,1+Assumptions!$B$32*MIN(1,ABS(F8)/ABS(Assumptions!$B$21)),MAX(0.1,1-Assumptions!$B$31*(F8/50)))))*J8)*Archetypes!$B$20)+((Archetypes!$B$11*(IF(F8<0,1+Assumptions!$B$32*MIN(1,ABS(F8)/ABS(Assumptions!$B$21)),MAX(0.1,1-Assumptions!$B$31*(F8/50)))))*J8*Archetypes!$B$20*Archetypes!$B$21)*Assumptions!$B$18)*(IF($D8=1,1,Assumptions!$B$7)))+(((((Archetypes!$B$11*(IF(F8<0,1+Assumptions!$B$32*MIN(1,ABS(F8)/ABS(Assumptions!$B$21)),MAX(0.1,1-Assumptions!$B$31*(F8/50)))))-((Archetypes!$B$11*(IF(F8<0,1+Assumptions!$B$32*MIN(1,ABS(F8)/ABS(Assumptions!$B$21)),MAX(0.1,1-Assumptions!$B$31*(F8/50)))))*J8)*Archetypes!$B$15)*(Archetypes!$B$13*IF(F8<0,1-Assumptions!$B$33*MIN(1,ABS(F8)/ABS(Assumptions!$B$21)),1))*5)+(((Archetypes!$B$11*(IF(F8<0,1+Assumptions!$B$32*MIN(1,ABS(F8)/ABS(Assumptions!$B$21)),MAX(0.1,1-Assumptions!$B$31*(F8/50)))))*J8*Archetypes!$B$15*Archetypes!$B$22)*(Archetypes!$B$13*IF(F8<0,1-Assumptions!$B$33*MIN(1,ABS(F8)/ABS(Assumptions!$B$21)),1))*5*Assumptions!$B$18))*IF(F8<0,Assumptions!$B$9,1)))*$E8 -> 500.66953 | O8: =(O7)+(N8)-(MAX(0,((O7)+(N8)-(P8)))*(IF(Archetypes!$B$27="",Assumptions!$B$11,Archetypes!$B$27))) -> 2790.7871 | P8: =Archetypes!$B$36 + (Assumptions!$B$67*(IF($E8=0,0,I8/$E8))*Assumptions!$B$71*(1+Assumptions!$B$68*(Archetypes!$B$14-1))) + (Assumptions!$B$69*Archetypes!$B$34*(IF($E8=0,0,I8/$E8))*Assumptions!$B$72*POWER(Assumptions!$B$70,Archetypes!$B$18-1)) -> 2590.9722 | Q8: =MAX(0,(O8)-(P8)) -> 199.81491 | S8: =T7 -> 19.977491 | T8: =MAX(Assumptions!$B$21,S8+U8) -> 23.232633 | U8: =((Y8*(Assumptions!$B$22+((Assumptions!$B$23-Assumptions!$B$22)*IF(V8>0,X8/V8,0)))*(1+Assumptions!$B$60*(Archetypes!$C$13-1)))+IF(Y8>V8,V8*Assumptions!$B$24,0)-IF(IF(V8>0,Z8/V8,1)<Assumptions!$B$61,((Z8*(Assumptions!$B$27*(1+Assumptions!$B$28*(Archetypes!$C$14-1))/(1+Assumptions!$B$29*(Archetypes!$C$12-1))))+(((V8*Archetypes!$C$17*IF(V8>0,Z8/V8,1)*Archetypes!$C$31)/100)*Assumptions!$B$30))*Assumptions!$B$62,((Z8*(Assumptions!$B$27*(1+Assumptions!$B$28*(Archetypes!$C$14-1))/(1+Assumptions!$B$29*(Archetypes!$C$12-1))))+(((V8*Archetypes!$C$17*IF(V8>0,Z8/V8,1)*Archetypes!$C$31)/100)*Assumptions!$B$30)))-(Assumptions!$B$25*Assumptions!$B$26*E8))*E8 -> 3.2551424 | V8: =(Archetypes!$C$11*(IF(S8<0,1+Assumptions!$B$32*MIN(1,ABS(S8)/ABS(Assumptions!$B$21)),MAX(0.1,1-Assumptions!$B$31*(S8/50)))))*$E8 -> 4.5616207 | W8: =Archetypes!$C$30 -> 0.038 | X8: =V8*W8 -> 0.17334158 | Y8: =((V8-X8)*Archetypes!$C$15)+(X8*Archetypes!$C$15*Archetypes!$C$22) -> 2.3068116 | Z8: =V8*Archetypes!$C$16 -> 2.0527293 | AA8: =(IF(S8<0,Assumptions!$B$8,IF(S8<10,Assumptions!$B$34,IF(S8<25,Assumptions!$B$35,Assumptions!$B$36))))*((((Archetypes!$C$5*Assumptions!$B$4+Archetypes!$C$6*Assumptions!$B$5)*60))+(Assumptions!$B$6*(((Archetypes!$C$11*(IF(S8<0,1+Assumptions!$B$32*MIN(1,ABS(S8)/ABS(Assumptions!$B$21)),MAX(0.1,1-Assumptions!$B$31*(S8/50)))))-((Archetypes!$C$11*(IF(S8<0,1+Assumptions!$B$32*MIN(1,ABS(S8)/ABS(Assumptions!$B$21)),MAX(0.1,1-Assumptions!$B$31*(S8/50)))))*W8)*Archetypes!$C$20)+((Archetypes!$C$11*(IF(S8<0,1+Assumptions!$B$32*MIN(1,ABS(S8)/ABS(Assumptions!$B$21)),MAX(0.1,1-Assumptions!$B$31*(S8/50)))))*W8*Archetypes!$C$20*Archetypes!$C$21)*Assumptions!$B$18)*(IF($D8=1,1,Assumptions!$B$7)))+(((((Archetypes!$C$11*(IF(S8<0,1+Assumptions!$B$32*MIN(1,ABS(S8)/ABS(Assumptions!$B$21)),MAX(0.1,1-Assumptions!$B$31*(S8/50)))))-((Archetypes!$C$11*(IF(S8<0,1+Assumptions!$B$32*MIN(1,ABS(S8)/ABS(Assumptions!$B$21)),MAX(0.1,1-Assumptions!$B$31*(S8/50)))))*W8)*Archetypes!$C$15)*(Archetypes!$C$13*IF(S8<0,1-Assumptions!$B$33*MIN(1,ABS(S8)/ABS(Assumptions!$B$21)),1))*5)+(((Archetypes!$C$11*(IF(S8<0,1+Assumptions!$B$32*MIN(1,ABS(S8)/ABS(Assumptions!$B$21)),MAX(0.1,1-Assumptions!$B$31*(S8/50)))))*W8*Archetypes!$C$15*Archetypes!$C$22)*(Archetypes!$C$13*IF(S8<0,1-Assumptions!$B$33*MIN(1,ABS(S8)/ABS(Assumptions!$B$21)),1))*5*Assumptions!$B$18))*IF(S8<0,Assumptions!$B$9,1)))*$E8 -> 994.31684 | AB8: =(AB7)+(AA8)-(MAX(0,((AB7)+(AA8)-(AC8)))*(IF(Archetypes!$C$27="",Assumptions!$B$11,Archetypes!$C$27))) -> 6049.9174 | AC8: =Archetypes!$C$36 + (Assumptions!$B$67*(IF($E8=0,0,V8/$E8))*Assumptions!$B$71*(1+Assumptions!$B$68*(Archetypes!$C$14-1))) + (Assumptions!$B$69*Archetypes!$C$34*(IF($E8=0,0,V8/$E8))*Assumptions!$B$72*POWER(Assumptions!$B$70,Archetypes!$C$18-1)) -> 9464.9059 | AD8: =MAX(0,(AB8)-(AC8)) -> 0 | AF8: =AG7 -> 43.25675 | AG8: =MAX(Assumptions!$B$21,AF8+AH8) -> 48.22048 | AH8: =((AL8*(Assumptions!$B$22+((Assumptions!$B$23-Assumptions!$B$22)*IF(AI8>0,AK8/AI8,0)))*(1+Assumptions!$B$60*(Archetypes!$D$13-1)))+IF(AL8>AI8,AI8*Assumptions!$B$24,0)-IF(IF(AI8>0,AM8/AI8,1)<Assumptions!$B$61,((AM8*(Assumptions!$B$27*(1+Assumptions!$B$28*(Archetypes!$D$14-1))/(1+Assumptions!$B$29*(Archetypes!$D$12-1))))+(((AI8*Archetypes!$D$17*IF(AI8>0,AM8/AI8,1)*Archetypes!$D$31)/100)*Assumptions!$B$30))*Assumptions!$B$62,((AM8*(Assumptions!$B$27*(1+Assumptions!$B$28*(Archetypes!$D$14-1))/(1+Assumptions!$B$29*(Archetypes!$D$12-1))))+(((AI8*Archetypes!$D$17*IF(AI8>0,AM8/AI8,1)*Archetypes!$D$31)/100)*Assumptions!$B$30)))-(Assumptions!$B$25*Assumptions!$B$26*E8))*E8 -> 4.9637294 | AI8: =(Archetypes!$D$11*(IF(AF8<0,1+Assumptions!$B$32*MIN(1,ABS(AF8)/ABS(Assumptions!$B$21)),MAX(0.1,1-Assumptions!$B$31*(AF8/50)))))*$E8 -> 1.442757 | AJ8: =Archetypes!$D$30 -> 0.104 | AK8: =AI8*AJ8 -> 0.15004673 | AL8: =((AI8-AK8)*Archetypes!$D$15)+(AK8*Archetypes!$D$15*Archetypes!$D$22) -> 2.2541635 | AM8: =AI8*Archetypes!$D$16 -> 0.2885514 | AN8: =(IF(AF8<0,Assumptions!$B$8,IF(AF8<10,Assumptions!$B$34,IF(AF8<25,Assumptions!$B$35,Assumptions!$B$36))))*((((Archetypes!$D$5*Assumptions!$B$4+Archetypes!$D$6*Assumptions!$B$5)*60))+(Assumptions!$B$6*(((Archetypes!$D$11*(IF(AF8<0,1+Assumptions!$B$32*MIN(1,ABS(AF8)/ABS(Assumptions!$B$21)),MAX(0.1,1-Assumptions!$B$31*(AF8/50)))))-((Archetypes!$D$11*(IF(AF8<0,1+Assumptions!$B$32*MIN(1,ABS(AF8)/ABS(Assumptions!$B$21)),MAX(0.1,1-Assumptions!$B$31*(AF8/50)))))*AJ8)*Archetypes!$D$20)+((Archetypes!$D$11*(IF(AF8<0,1+Assumptions!$B$32*MIN(1,ABS(AF8)/ABS(Assumptions!$B$21)),MAX(0.1,1-Assumptions!$B$31*(AF8/50)))))*AJ8*Archetypes!$D$20*Archetypes!$D$21)*Assumptions!$B$18)*(IF($D8=1,1,Assumptions!$B$7)))+(((((Archetypes!$D$11*(IF(AF8<0,1+Assumptions!$B$32*MIN(1,ABS(AF8)/ABS(Assumptions!$B$21)),MAX(0.1,1-Assumptions!$B$31*(AF8/50)))))-((Archetypes!$D$11*(IF(AF8<0,1+Assumptions!$B$32*MIN(1,ABS(AF8)/ABS(Assumptions!$B$21)),MAX(0.1,1-Assumptions!$B$31*(AF8/50)))))*AJ8)*Archetypes!$D$15)*(Archetypes!$D$13*IF(AF8<0,1-Assumptions!$B$33*MIN(1,ABS(AF8)/ABS(Assumptions!$B$21)),1))*5)+(((Archetypes!$D$11*(IF(AF8<0,1+Assumptions!$B$32*MIN(1,ABS(AF8)/ABS(Assumptions!$B$21)),MAX(0.1,1-Assumptions!$B$31*(AF8/50)))))*AJ8*Archetypes!$D$15*Archetypes!$D$22)*(Archetypes!$D$13*IF(AF8<0,1-Assumptions!$B$33*MIN(1,ABS(AF8)/ABS(Assumptions!$B$21)),1))*5*Assumptions!$B$18))*IF(AF8<0,Assumptions!$B$9,1)))*$E8 -> 1216.3239 | AO8: =(AO7)+(AN8)-(MAX(0,((AO7)+(AN8)-(AP8)))*(IF(Archetypes!$D$27="",Assumptions!$B$11,Archetypes!$D$27))) -> 8623.9081 | AP8: =Archetypes!$D$36 + (Assumptions!$B$67*(IF($E8=0,0,AI8/$E8))*Assumptions!$B$71*(1+Assumptions!$B$68*(Archetypes!$D$14-1))) + (Assumptions!$B$69*Archetypes!$D$34*(IF($E8=0,0,AI8/$E8))*Assumptions!$B$72*POWER(Assumptions!$B$70,Archetypes!$D$18-1)) -> 20994.21 | AQ8: =MAX(0,(AO8)-(AP8)) -> 0
